[15/Jul/2023 17:02:51] ERROR [django.request:241] Internal Server Error: /operations/admin_deposit
Traceback (most recent call last):
  File "/home/dennis/projects/saving_record/savingrecord/userdata/views.py", line 38, in admin_deposit_simba
    d_account = Account.objects.get(account_number=account)
  File "/home/dennis/projects/saving_record/saving/lib/python3.10/site-packages/django/db/models/manager.py", line 87, in manager_method
    return getattr(self.get_queryset(), name)(*args, **kwargs)
  File "/home/dennis/projects/saving_record/saving/lib/python3.10/site-packages/django/db/models/query.py", line 637, in get
    raise self.model.DoesNotExist(
savings.models.Account.DoesNotExist: Account matching query does not exist.

During handling of the above exception, another exception occurred:

Traceback (most recent call last):
  File "/home/dennis/projects/saving_record/saving/lib/python3.10/site-packages/django/core/handlers/exception.py", line 55, in inner
    response = get_response(request)
  File "/home/dennis/projects/saving_record/saving/lib/python3.10/site-packages/django/core/handlers/base.py", line 197, in _get_response
    response = wrapped_callback(request, *callback_args, **callback_kwargs)
  File "/home/dennis/projects/saving_record/savingrecord/userdata/views.py", line 40, in admin_deposit_simba
    except Account.DoesNot.Exist:
AttributeError: type object 'Account' has no attribute 'DoesNot'
[15/Jul/2023 17:02:51] ERROR [django.server:212] "POST /operations/admin_deposit HTTP/1.1" 500 85054
[15/Jul/2023 17:04:50] ERROR [django.request:241] Internal Server Error: /operations/admin_deposit
Traceback (most recent call last):
  File "/home/dennis/projects/saving_record/savingrecord/userdata/views.py", line 38, in admin_deposit_simba
    d_account = Account.objects.get(account_number=account)
  File "/home/dennis/projects/saving_record/saving/lib/python3.10/site-packages/django/db/models/manager.py", line 87, in manager_method
    return getattr(self.get_queryset(), name)(*args, **kwargs)
  File "/home/dennis/projects/saving_record/saving/lib/python3.10/site-packages/django/db/models/query.py", line 637, in get
    raise self.model.DoesNotExist(
savings.models.Account.DoesNotExist: Account matching query does not exist.

During handling of the above exception, another exception occurred:

Traceback (most recent call last):
  File "/home/dennis/projects/saving_record/saving/lib/python3.10/site-packages/django/core/handlers/exception.py", line 55, in inner
    response = get_response(request)
  File "/home/dennis/projects/saving_record/saving/lib/python3.10/site-packages/django/core/handlers/base.py", line 197, in _get_response
    response = wrapped_callback(request, *callback_args, **callback_kwargs)
  File "/home/dennis/projects/saving_record/savingrecord/userdata/views.py", line 42, in admin_deposit_simba
    return redirect("admin_deposit_simba")
  File "/home/dennis/projects/saving_record/saving/lib/python3.10/site-packages/django/shortcuts.py", line 48, in redirect
    return redirect_class(resolve_url(to, *args, **kwargs))
  File "/home/dennis/projects/saving_record/saving/lib/python3.10/site-packages/django/shortcuts.py", line 145, in resolve_url
    return reverse(to, args=args, kwargs=kwargs)
  File "/home/dennis/projects/saving_record/saving/lib/python3.10/site-packages/django/urls/base.py", line 88, in reverse
    return resolver._reverse_with_prefix(view, prefix, *args, **kwargs)
  File "/home/dennis/projects/saving_record/saving/lib/python3.10/site-packages/django/urls/resolvers.py", line 828, in _reverse_with_prefix
    raise NoReverseMatch(msg)
django.urls.exceptions.NoReverseMatch: Reverse for 'admin_deposit_simba' not found. 'admin_deposit_simba' is not a valid view function or pattern name.
[15/Jul/2023 17:04:50] ERROR [django.server:212] "POST /operations/admin_deposit HTTP/1.1" 500 103661
[15/Jul/2023 17:09:06] ERROR [django.request:241] Internal Server Error: /operations/admin_deposit
Traceback (most recent call last):
  File "/home/dennis/projects/saving_record/savingrecord/userdata/views.py", line 38, in admin_deposit_simba
    d_account = Account.objects.get(account_number=account)
  File "/home/dennis/projects/saving_record/saving/lib/python3.10/site-packages/django/db/models/manager.py", line 87, in manager_method
    return getattr(self.get_queryset(), name)(*args, **kwargs)
  File "/home/dennis/projects/saving_record/saving/lib/python3.10/site-packages/django/db/models/query.py", line 637, in get
    raise self.model.DoesNotExist(
savings.models.Account.DoesNotExist: Account matching query does not exist.

During handling of the above exception, another exception occurred:

Traceback (most recent call last):
  File "/home/dennis/projects/saving_record/saving/lib/python3.10/site-packages/django/core/handlers/exception.py", line 55, in inner
    response = get_response(request)
  File "/home/dennis/projects/saving_record/saving/lib/python3.10/site-packages/django/core/handlers/base.py", line 197, in _get_response
    response = wrapped_callback(request, *callback_args, **callback_kwargs)
  File "/home/dennis/projects/saving_record/savingrecord/userdata/views.py", line 42, in admin_deposit_simba
    return redirect("admin_deposit_simba")
  File "/home/dennis/projects/saving_record/saving/lib/python3.10/site-packages/django/shortcuts.py", line 48, in redirect
    return redirect_class(resolve_url(to, *args, **kwargs))
  File "/home/dennis/projects/saving_record/saving/lib/python3.10/site-packages/django/shortcuts.py", line 145, in resolve_url
    return reverse(to, args=args, kwargs=kwargs)
  File "/home/dennis/projects/saving_record/saving/lib/python3.10/site-packages/django/urls/base.py", line 88, in reverse
    return resolver._reverse_with_prefix(view, prefix, *args, **kwargs)
  File "/home/dennis/projects/saving_record/saving/lib/python3.10/site-packages/django/urls/resolvers.py", line 828, in _reverse_with_prefix
    raise NoReverseMatch(msg)
django.urls.exceptions.NoReverseMatch: Reverse for 'admin_deposit_simba' not found. 'admin_deposit_simba' is not a valid view function or pattern name.
[15/Jul/2023 17:09:06] ERROR [django.server:212] "POST /operations/admin_deposit HTTP/1.1" 500 103908
[15/Jul/2023 17:16:48] ERROR [django.request:241] Internal Server Error: /operations/admin_deposit
Traceback (most recent call last):
  File "/home/dennis/projects/saving_record/saving/lib/python3.10/site-packages/django/core/handlers/exception.py", line 55, in inner
    response = get_response(request)
  File "/home/dennis/projects/saving_record/saving/lib/python3.10/site-packages/django/core/handlers/base.py", line 197, in _get_response
    response = wrapped_callback(request, *callback_args, **callback_kwargs)
  File "/home/dennis/projects/saving_record/savingrecord/userdata/views.py", line 32, in admin_deposit_simba
    status = not_negative(deposit_amount)
  File "/home/dennis/projects/saving_record/savingrecord/savings/classes.py", line 73, in not_negative
    if int(amount) > 0:
ValueError: invalid literal for int() with base 10: 'hjjkk'
[15/Jul/2023 17:16:48] ERROR [django.server:212] "POST /operations/admin_deposit HTTP/1.1" 500 74261
[15/Jul/2023 17:35:26] ERROR [django.request:241] Internal Server Error: /operations/admin_deposit
Traceback (most recent call last):
  File "/home/dennis/projects/saving_record/saving/lib/python3.10/site-packages/django/core/handlers/exception.py", line 55, in inner
    response = get_response(request)
  File "/home/dennis/projects/saving_record/saving/lib/python3.10/site-packages/django/core/handlers/base.py", line 197, in _get_response
    response = wrapped_callback(request, *callback_args, **callback_kwargs)
  File "/home/dennis/projects/saving_record/savingrecord/userdata/views.py", line 38, in admin_deposit_simba
    return redirect("userdata:admin_withdraw_simba")
  File "/home/dennis/projects/saving_record/saving/lib/python3.10/site-packages/django/shortcuts.py", line 48, in redirect
    return redirect_class(resolve_url(to, *args, **kwargs))
  File "/home/dennis/projects/saving_record/saving/lib/python3.10/site-packages/django/shortcuts.py", line 145, in resolve_url
    return reverse(to, args=args, kwargs=kwargs)
  File "/home/dennis/projects/saving_record/saving/lib/python3.10/site-packages/django/urls/base.py", line 88, in reverse
    return resolver._reverse_with_prefix(view, prefix, *args, **kwargs)
  File "/home/dennis/projects/saving_record/saving/lib/python3.10/site-packages/django/urls/resolvers.py", line 828, in _reverse_with_prefix
    raise NoReverseMatch(msg)
django.urls.exceptions.NoReverseMatch: Reverse for 'admin_withdraw_simba' not found. 'admin_withdraw_simba' is not a valid view function or pattern name.
[15/Jul/2023 17:35:26] ERROR [django.server:212] "POST /operations/admin_deposit HTTP/1.1" 500 90736
[15/Jul/2023 17:54:33] ERROR [django.request:241] Internal Server Error: /operations/admin_deposit
Traceback (most recent call last):
  File "/home/dennis/projects/saving_record/savingrecord/userdata/views.py", line 33, in admin_deposit_simba
    deposit_amount = Decimal(amount)
NameError: name 'Decimal' is not defined

During handling of the above exception, another exception occurred:

Traceback (most recent call last):
  File "/home/dennis/projects/saving_record/saving/lib/python3.10/site-packages/django/core/handlers/exception.py", line 55, in inner
    response = get_response(request)
  File "/home/dennis/projects/saving_record/saving/lib/python3.10/site-packages/django/core/handlers/base.py", line 197, in _get_response
    response = wrapped_callback(request, *callback_args, **callback_kwargs)
  File "/home/dennis/projects/saving_record/savingrecord/userdata/views.py", line 34, in admin_deposit_simba
    except InvalidOperation as e:
NameError: name 'InvalidOperation' is not defined
[15/Jul/2023 17:54:33] ERROR [django.server:212] "POST /operations/admin_deposit HTTP/1.1" 500 75457
[15/Jul/2023 17:56:03] ERROR [django.request:241] Internal Server Error: /operations/admin_deposit
Traceback (most recent call last):
  File "/home/dennis/projects/saving_record/saving/lib/python3.10/site-packages/django/core/handlers/exception.py", line 55, in inner
    response = get_response(request)
  File "/home/dennis/projects/saving_record/saving/lib/python3.10/site-packages/django/core/handlers/base.py", line 197, in _get_response
    response = wrapped_callback(request, *callback_args, **callback_kwargs)
  File "/home/dennis/projects/saving_record/savingrecord/userdata/views.py", line 34, in admin_deposit_simba
    deposit_amount = Decimal(amount)
NameError: name 'amount' is not defined
[15/Jul/2023 17:56:03] ERROR [django.server:212] "POST /operations/admin_deposit HTTP/1.1" 500 70815
[15/Jul/2023 17:56:48] ERROR [django.request:241] Internal Server Error: /operations/admin_deposit
Traceback (most recent call last):
  File "/home/dennis/projects/saving_record/saving/lib/python3.10/site-packages/django/core/handlers/exception.py", line 55, in inner
    response = get_response(request)
  File "/home/dennis/projects/saving_record/saving/lib/python3.10/site-packages/django/utils/deprecation.py", line 136, in __call__
    response = self.process_response(request, response)
  File "/home/dennis/projects/saving_record/saving/lib/python3.10/site-packages/django/middleware/clickjacking.py", line 27, in process_response
    if response.get("X-Frame-Options") is not None:
AttributeError: 'str' object has no attribute 'get'
[15/Jul/2023 17:56:48] ERROR [django.server:212] "POST /operations/admin_deposit HTTP/1.1" 500 69843
[15/Jul/2023 18:01:09] ERROR [django.request:241] Internal Server Error: /operations/admin_deposit
Traceback (most recent call last):
  File "/home/dennis/projects/saving_record/savingrecord/userdata/views.py", line 34, in admin_deposit_simba
    deposit_amount = Decimal(deposit_amount)
decimal.InvalidOperation: [<class 'decimal.ConversionSyntax'>]

During handling of the above exception, another exception occurred:

Traceback (most recent call last):
  File "/home/dennis/projects/saving_record/saving/lib/python3.10/site-packages/django/core/handlers/exception.py", line 55, in inner
    response = get_response(request)
  File "/home/dennis/projects/saving_record/saving/lib/python3.10/site-packages/django/core/handlers/base.py", line 197, in _get_response
    response = wrapped_callback(request, *callback_args, **callback_kwargs)
  File "/home/dennis/projects/saving_record/savingrecord/userdata/views.py", line 35, in admin_deposit_simba
    except decimal.InvalidOperation:
NameError: name 'decimal' is not defined
[15/Jul/2023 18:01:09] ERROR [django.server:212] "POST /operations/admin_deposit HTTP/1.1" 500 75480
[15/Jul/2023 18:05:49] ERROR [django.request:241] Internal Server Error: /operations/admin_deposit
Traceback (most recent call last):
  File "/home/dennis/projects/saving_record/saving/lib/python3.10/site-packages/django/core/handlers/exception.py", line 55, in inner
    response = get_response(request)
  File "/home/dennis/projects/saving_record/saving/lib/python3.10/site-packages/django/utils/deprecation.py", line 136, in __call__
    response = self.process_response(request, response)
  File "/home/dennis/projects/saving_record/saving/lib/python3.10/site-packages/django/middleware/clickjacking.py", line 27, in process_response
    if response.get("X-Frame-Options") is not None:
AttributeError: 'str' object has no attribute 'get'
[15/Jul/2023 18:05:49] ERROR [django.server:212] "POST /operations/admin_deposit HTTP/1.1" 500 69843
[15/Jul/2023 18:09:19] ERROR [django.request:241] Internal Server Error: /operations/admin_deposit
Traceback (most recent call last):
  File "/home/dennis/projects/saving_record/saving/lib/python3.10/site-packages/django/core/handlers/exception.py", line 55, in inner
    response = get_response(request)
  File "/home/dennis/projects/saving_record/saving/lib/python3.10/site-packages/django/utils/deprecation.py", line 136, in __call__
    response = self.process_response(request, response)
  File "/home/dennis/projects/saving_record/saving/lib/python3.10/site-packages/django/middleware/clickjacking.py", line 27, in process_response
    if response.get("X-Frame-Options") is not None:
AttributeError: 'str' object has no attribute 'get'
[15/Jul/2023 18:09:19] ERROR [django.server:212] "POST /operations/admin_deposit HTTP/1.1" 500 69843
[15/Jul/2023 18:10:25] ERROR [django.request:241] Internal Server Error: /operations/admin_deposit
Traceback (most recent call last):
  File "/home/dennis/projects/saving_record/saving/lib/python3.10/site-packages/django/core/handlers/exception.py", line 55, in inner
    response = get_response(request)
  File "/home/dennis/projects/saving_record/saving/lib/python3.10/site-packages/django/core/handlers/base.py", line 197, in _get_response
    response = wrapped_callback(request, *callback_args, **callback_kwargs)
  File "/home/dennis/projects/saving_record/savingrecord/userdata/views.py", line 34, in admin_deposit_simba
    status = not_negative(deposit_amount)
  File "/home/dennis/projects/saving_record/savingrecord/savings/classes.py", line 72, in not_negative
    if int(amount) > 0:
ValueError: invalid literal for int() with base 10: 'hjjkk'
[15/Jul/2023 18:10:25] ERROR [django.server:212] "POST /operations/admin_deposit HTTP/1.1" 500 74456
[15/Jul/2023 18:16:25] ERROR [django.request:241] Internal Server Error: /operations/admin_deposit
Traceback (most recent call last):
  File "/home/dennis/projects/saving_record/saving/lib/python3.10/site-packages/django/core/handlers/exception.py", line 55, in inner
    response = get_response(request)
  File "/home/dennis/projects/saving_record/saving/lib/python3.10/site-packages/django/core/handlers/base.py", line 197, in _get_response
    response = wrapped_callback(request, *callback_args, **callback_kwargs)
  File "/home/dennis/projects/saving_record/savingrecord/userdata/views.py", line 35, in admin_deposit_simba
    if status == "negative":
NameError: name 'status' is not defined
[15/Jul/2023 18:16:25] ERROR [django.server:212] "POST /operations/admin_deposit HTTP/1.1" 500 70955
[15/Jul/2023 18:17:51] ERROR [django.request:241] Internal Server Error: /operations/admin_deposit
Traceback (most recent call last):
  File "/home/dennis/projects/saving_record/saving/lib/python3.10/site-packages/django/core/handlers/exception.py", line 55, in inner
    response = get_response(request)
  File "/home/dennis/projects/saving_record/saving/lib/python3.10/site-packages/django/utils/deprecation.py", line 136, in __call__
    response = self.process_response(request, response)
  File "/home/dennis/projects/saving_record/saving/lib/python3.10/site-packages/django/middleware/clickjacking.py", line 27, in process_response
    if response.get("X-Frame-Options") is not None:
AttributeError: 'str' object has no attribute 'get'
[15/Jul/2023 18:17:51] ERROR [django.server:212] "POST /operations/admin_deposit HTTP/1.1" 500 69843
[15/Jul/2023 18:18:50] ERROR [django.request:241] Internal Server Error: /operations/admin_deposit
Traceback (most recent call last):
  File "/home/dennis/projects/saving_record/saving/lib/python3.10/site-packages/django/core/handlers/exception.py", line 55, in inner
    response = get_response(request)
  File "/home/dennis/projects/saving_record/saving/lib/python3.10/site-packages/django/utils/deprecation.py", line 136, in __call__
    response = self.process_response(request, response)
  File "/home/dennis/projects/saving_record/saving/lib/python3.10/site-packages/django/middleware/clickjacking.py", line 27, in process_response
    if response.get("X-Frame-Options") is not None:
AttributeError: 'str' object has no attribute 'get'
[15/Jul/2023 18:18:50] ERROR [django.server:212] "POST /operations/admin_deposit HTTP/1.1" 500 69841
[15/Jul/2023 18:20:55] ERROR [django.request:241] Internal Server Error: /operations/admin_deposit
Traceback (most recent call last):
  File "/home/dennis/projects/saving_record/saving/lib/python3.10/site-packages/django/core/handlers/exception.py", line 55, in inner
    response = get_response(request)
  File "/home/dennis/projects/saving_record/saving/lib/python3.10/site-packages/django/utils/deprecation.py", line 136, in __call__
    response = self.process_response(request, response)
  File "/home/dennis/projects/saving_record/saving/lib/python3.10/site-packages/django/middleware/clickjacking.py", line 27, in process_response
    if response.get("X-Frame-Options") is not None:
AttributeError: 'str' object has no attribute 'get'
[15/Jul/2023 18:20:55] ERROR [django.server:212] "POST /operations/admin_deposit HTTP/1.1" 500 69841
[15/Jul/2023 18:23:07] ERROR [django.request:241] Internal Server Error: /operations/admin_deposit
Traceback (most recent call last):
  File "/home/dennis/projects/saving_record/saving/lib/python3.10/site-packages/django/core/handlers/exception.py", line 55, in inner
    response = get_response(request)
  File "/home/dennis/projects/saving_record/saving/lib/python3.10/site-packages/django/core/handlers/base.py", line 197, in _get_response
    response = wrapped_callback(request, *callback_args, **callback_kwargs)
  File "/home/dennis/projects/saving_record/savingrecord/userdata/views.py", line 54, in admin_deposit_simba
    d_account.account_balance += Decimal(deposit_amount)
decimal.InvalidOperation: [<class 'decimal.ConversionSyntax'>]
[15/Jul/2023 18:23:07] ERROR [django.server:212] "POST /operations/admin_deposit HTTP/1.1" 500 71686
[15/Jul/2023 18:26:31] ERROR [django.request:241] Internal Server Error: /operations/admin_deposit
Traceback (most recent call last):
  File "/home/dennis/projects/saving_record/saving/lib/python3.10/site-packages/django/core/handlers/exception.py", line 55, in inner
    response = get_response(request)
  File "/home/dennis/projects/saving_record/saving/lib/python3.10/site-packages/django/utils/deprecation.py", line 136, in __call__
    response = self.process_response(request, response)
  File "/home/dennis/projects/saving_record/saving/lib/python3.10/site-packages/django/middleware/clickjacking.py", line 27, in process_response
    if response.get("X-Frame-Options") is not None:
AttributeError: 'str' object has no attribute 'get'
[15/Jul/2023 18:26:31] ERROR [django.server:212] "POST /operations/admin_deposit HTTP/1.1" 500 69833
[15/Jul/2023 18:56:09] ERROR [django.request:241] Internal Server Error: /operations/admin_deposit
Traceback (most recent call last):
  File "/home/dennis/projects/saving_record/saving/lib/python3.10/site-packages/django/utils/datastructures.py", line 84, in __getitem__
    list_ = super().__getitem__(key)
KeyError: 'deposit_amount'

During handling of the above exception, another exception occurred:

Traceback (most recent call last):
  File "/home/dennis/projects/saving_record/saving/lib/python3.10/site-packages/django/core/handlers/exception.py", line 55, in inner
    response = get_response(request)
  File "/home/dennis/projects/saving_record/saving/lib/python3.10/site-packages/django/core/handlers/base.py", line 197, in _get_response
    response = wrapped_callback(request, *callback_args, **callback_kwargs)
  File "/home/dennis/projects/saving_record/savingrecord/userdata/views.py", line 30, in admin_deposit_simba
    deposit_amount = request.POST["deposit_amount"]
  File "/home/dennis/projects/saving_record/saving/lib/python3.10/site-packages/django/utils/datastructures.py", line 86, in __getitem__
    raise MultiValueDictKeyError(key)
django.utils.datastructures.MultiValueDictKeyError: 'deposit_amount'
[15/Jul/2023 18:56:09] ERROR [django.server:212] "POST /operations/admin_deposit HTTP/1.1" 500 79031
[15/Jul/2023 18:58:31] ERROR [django.request:241] Internal Server Error: /operations/admin_deposit
Traceback (most recent call last):
  File "/home/dennis/projects/saving_record/saving/lib/python3.10/site-packages/django/utils/datastructures.py", line 84, in __getitem__
    list_ = super().__getitem__(key)
KeyError: 'deposit_amount'

During handling of the above exception, another exception occurred:

Traceback (most recent call last):
  File "/home/dennis/projects/saving_record/saving/lib/python3.10/site-packages/django/core/handlers/exception.py", line 55, in inner
    response = get_response(request)
  File "/home/dennis/projects/saving_record/saving/lib/python3.10/site-packages/django/core/handlers/base.py", line 197, in _get_response
    response = wrapped_callback(request, *callback_args, **callback_kwargs)
  File "/home/dennis/projects/saving_record/savingrecord/userdata/views.py", line 30, in admin_deposit_simba
    deposit_amount = request.POST["deposit_amount"]
  File "/home/dennis/projects/saving_record/saving/lib/python3.10/site-packages/django/utils/datastructures.py", line 86, in __getitem__
    raise MultiValueDictKeyError(key)
django.utils.datastructures.MultiValueDictKeyError: 'deposit_amount'
[15/Jul/2023 18:58:31] ERROR [django.server:212] "POST /operations/admin_deposit HTTP/1.1" 500 79031
[15/Jul/2023 19:00:26] ERROR [django.request:241] Internal Server Error: /operations/admin_withdraw
Traceback (most recent call last):
  File "/home/dennis/projects/saving_record/saving/lib/python3.10/site-packages/django/core/handlers/exception.py", line 55, in inner
    response = get_response(request)
  File "/home/dennis/projects/saving_record/saving/lib/python3.10/site-packages/django/core/handlers/base.py", line 197, in _get_response
    response = wrapped_callback(request, *callback_args, **callback_kwargs)
  File "/home/dennis/projects/saving_record/savingrecord/userdata/views.py", line 120, in admin_widthdraw
    return render(request, "userdata/admin_withdraw_simba.html", {})
  File "/home/dennis/projects/saving_record/saving/lib/python3.10/site-packages/django/shortcuts.py", line 24, in render
    content = loader.render_to_string(template_name, context, request, using=using)
  File "/home/dennis/projects/saving_record/saving/lib/python3.10/site-packages/django/template/loader.py", line 62, in render_to_string
    return template.render(context, request)
  File "/home/dennis/projects/saving_record/saving/lib/python3.10/site-packages/django/template/backends/django.py", line 61, in render
    return self.template.render(context)
  File "/home/dennis/projects/saving_record/saving/lib/python3.10/site-packages/django/template/base.py", line 175, in render
    return self._render(context)
  File "/home/dennis/projects/saving_record/saving/lib/python3.10/site-packages/django/template/base.py", line 167, in _render
    return self.nodelist.render(context)
  File "/home/dennis/projects/saving_record/saving/lib/python3.10/site-packages/django/template/base.py", line 1005, in render
    return SafeString("".join([node.render_annotated(context) for node in self]))
  File "/home/dennis/projects/saving_record/saving/lib/python3.10/site-packages/django/template/base.py", line 1005, in <listcomp>
    return SafeString("".join([node.render_annotated(context) for node in self]))
  File "/home/dennis/projects/saving_record/saving/lib/python3.10/site-packages/django/template/base.py", line 966, in render_annotated
    return self.render(context)
  File "/home/dennis/projects/saving_record/saving/lib/python3.10/site-packages/django/template/loader_tags.py", line 157, in render
    return compiled_parent._render(context)
  File "/home/dennis/projects/saving_record/saving/lib/python3.10/site-packages/django/template/base.py", line 167, in _render
    return self.nodelist.render(context)
  File "/home/dennis/projects/saving_record/saving/lib/python3.10/site-packages/django/template/base.py", line 1005, in render
    return SafeString("".join([node.render_annotated(context) for node in self]))
  File "/home/dennis/projects/saving_record/saving/lib/python3.10/site-packages/django/template/base.py", line 1005, in <listcomp>
    return SafeString("".join([node.render_annotated(context) for node in self]))
  File "/home/dennis/projects/saving_record/saving/lib/python3.10/site-packages/django/template/base.py", line 966, in render_annotated
    return self.render(context)
  File "/home/dennis/projects/saving_record/saving/lib/python3.10/site-packages/django/template/loader_tags.py", line 63, in render
    result = block.nodelist.render(context)
  File "/home/dennis/projects/saving_record/saving/lib/python3.10/site-packages/django/template/base.py", line 1005, in render
    return SafeString("".join([node.render_annotated(context) for node in self]))
  File "/home/dennis/projects/saving_record/saving/lib/python3.10/site-packages/django/template/base.py", line 1005, in <listcomp>
    return SafeString("".join([node.render_annotated(context) for node in self]))
  File "/home/dennis/projects/saving_record/saving/lib/python3.10/site-packages/django/template/base.py", line 966, in render_annotated
    return self.render(context)
  File "/home/dennis/projects/saving_record/saving/lib/python3.10/site-packages/django/template/defaulttags.py", line 471, in render
    url = reverse(view_name, args=args, kwargs=kwargs, current_app=current_app)
  File "/home/dennis/projects/saving_record/saving/lib/python3.10/site-packages/django/urls/base.py", line 88, in reverse
    return resolver._reverse_with_prefix(view, prefix, *args, **kwargs)
  File "/home/dennis/projects/saving_record/saving/lib/python3.10/site-packages/django/urls/resolvers.py", line 828, in _reverse_with_prefix
    raise NoReverseMatch(msg)
django.urls.exceptions.NoReverseMatch: Reverse for 'staff' not found. 'staff' is not a valid view function or pattern name.
[15/Jul/2023 19:00:26] ERROR [django.server:212] "GET /operations/admin_withdraw HTTP/1.1" 500 171419
[15/Jul/2023 19:01:28] ERROR [django.request:241] Internal Server Error: /operations/admin_withdraw
Traceback (most recent call last):
  File "/home/dennis/projects/saving_record/saving/lib/python3.10/site-packages/django/core/handlers/exception.py", line 55, in inner
    response = get_response(request)
  File "/home/dennis/projects/saving_record/saving/lib/python3.10/site-packages/django/core/handlers/base.py", line 197, in _get_response
    response = wrapped_callback(request, *callback_args, **callback_kwargs)
  File "/home/dennis/projects/saving_record/savingrecord/userdata/views.py", line 109, in admin_widthdraw
    w_account.total_deposit -= deposit_amount
NameError: name 'deposit_amount' is not defined
[15/Jul/2023 19:01:28] ERROR [django.server:212] "POST /operations/admin_withdraw HTTP/1.1" 500 71952
[16/Jul/2023 12:46:12] ERROR [django.request:241] Internal Server Error: /operations/approve_business_number
Traceback (most recent call last):
  File "/home/dennis/projects/saving_record/saving/lib/python3.10/site-packages/django/core/handlers/exception.py", line 55, in inner
    response = get_response(request)
  File "/home/dennis/projects/saving_record/saving/lib/python3.10/site-packages/django/core/handlers/base.py", line 197, in _get_response
    response = wrapped_callback(request, *callback_args, **callback_kwargs)
  File "/home/dennis/projects/saving_record/savingrecord/userdata/views.py", line 127, in business_number_approval
    bus_num = Company.objects.filter(buss_number__isnull=True).fiest()
NameError: name 'Company' is not defined
[16/Jul/2023 12:46:12] ERROR [django.server:212] "GET /operations/approve_business_number HTTP/1.1" 500 145
[16/Jul/2023 12:46:47] ERROR [django.request:241] Internal Server Error: /operations/approve_business_number
Traceback (most recent call last):
  File "/home/dennis/projects/saving_record/saving/lib/python3.10/site-packages/django/core/handlers/exception.py", line 55, in inner
    response = get_response(request)
  File "/home/dennis/projects/saving_record/saving/lib/python3.10/site-packages/django/core/handlers/base.py", line 197, in _get_response
    response = wrapped_callback(request, *callback_args, **callback_kwargs)
  File "/home/dennis/projects/saving_record/savingrecord/userdata/views.py", line 127, in business_number_approval
    bus_num = Company.objects.filter(buss_number__isnull=True).fiest()
NameError: name 'Company' is not defined
[16/Jul/2023 12:46:47] ERROR [django.server:212] "GET /operations/approve_business_number HTTP/1.1" 500 69664
[16/Jul/2023 12:46:48] ERROR [django.request:241] Internal Server Error: /operations/approve_business_number
Traceback (most recent call last):
  File "/home/dennis/projects/saving_record/saving/lib/python3.10/site-packages/django/core/handlers/exception.py", line 55, in inner
    response = get_response(request)
  File "/home/dennis/projects/saving_record/saving/lib/python3.10/site-packages/django/core/handlers/base.py", line 197, in _get_response
    response = wrapped_callback(request, *callback_args, **callback_kwargs)
  File "/home/dennis/projects/saving_record/savingrecord/userdata/views.py", line 127, in business_number_approval
    bus_num = Company.objects.filter(buss_number__isnull=True).fiest()
NameError: name 'Company' is not defined
[16/Jul/2023 12:46:48] ERROR [django.server:212] "GET /operations/approve_business_number HTTP/1.1" 500 69664
[16/Jul/2023 12:46:51] ERROR [django.request:241] Internal Server Error: /operations/approve_business_number
Traceback (most recent call last):
  File "/home/dennis/projects/saving_record/saving/lib/python3.10/site-packages/django/core/handlers/exception.py", line 55, in inner
    response = get_response(request)
  File "/home/dennis/projects/saving_record/saving/lib/python3.10/site-packages/django/core/handlers/base.py", line 197, in _get_response
    response = wrapped_callback(request, *callback_args, **callback_kwargs)
  File "/home/dennis/projects/saving_record/savingrecord/userdata/views.py", line 127, in business_number_approval
    bus_num = Company.objects.filter(buss_number__isnull=True).fiest()
NameError: name 'Company' is not defined
[16/Jul/2023 12:46:51] ERROR [django.server:212] "GET /operations/approve_business_number HTTP/1.1" 500 69527
[16/Jul/2023 12:48:09] ERROR [django.request:241] Internal Server Error: /operations/approve_business_number
Traceback (most recent call last):
  File "/home/dennis/projects/saving_record/saving/lib/python3.10/site-packages/django/core/handlers/exception.py", line 55, in inner
    response = get_response(request)
  File "/home/dennis/projects/saving_record/saving/lib/python3.10/site-packages/django/core/handlers/base.py", line 197, in _get_response
    response = wrapped_callback(request, *callback_args, **callback_kwargs)
  File "/home/dennis/projects/saving_record/savingrecord/userdata/views.py", line 128, in business_number_approval
    bus_num = Company.objects.filter(buss_number__isnull=True).fiest()
  File "/home/dennis/projects/saving_record/saving/lib/python3.10/site-packages/django/db/models/manager.py", line 87, in manager_method
    return getattr(self.get_queryset(), name)(*args, **kwargs)
  File "/home/dennis/projects/saving_record/saving/lib/python3.10/site-packages/django/db/models/query.py", line 1436, in filter
    return self._filter_or_exclude(False, args, kwargs)
  File "/home/dennis/projects/saving_record/saving/lib/python3.10/site-packages/django/db/models/query.py", line 1454, in _filter_or_exclude
    clone._filter_or_exclude_inplace(negate, args, kwargs)
  File "/home/dennis/projects/saving_record/saving/lib/python3.10/site-packages/django/db/models/query.py", line 1461, in _filter_or_exclude_inplace
    self._query.add_q(Q(*args, **kwargs))
  File "/home/dennis/projects/saving_record/saving/lib/python3.10/site-packages/django/db/models/sql/query.py", line 1534, in add_q
    clause, _ = self._add_q(q_object, self.used_aliases)
  File "/home/dennis/projects/saving_record/saving/lib/python3.10/site-packages/django/db/models/sql/query.py", line 1565, in _add_q
    child_clause, needed_inner = self.build_filter(
  File "/home/dennis/projects/saving_record/saving/lib/python3.10/site-packages/django/db/models/sql/query.py", line 1415, in build_filter
    lookups, parts, reffed_expression = self.solve_lookup_type(arg, summarize)
  File "/home/dennis/projects/saving_record/saving/lib/python3.10/site-packages/django/db/models/sql/query.py", line 1225, in solve_lookup_type
    _, field, _, lookup_parts = self.names_to_path(lookup_splitted, self.get_meta())
  File "/home/dennis/projects/saving_record/saving/lib/python3.10/site-packages/django/db/models/sql/query.py", line 1713, in names_to_path
    raise FieldError(
django.core.exceptions.FieldError: Cannot resolve keyword 'buss_number' into field. Choices are: address, admin_review, approved, business_numbers, contact, country, email, id, name, registered_on
[16/Jul/2023 12:48:09] ERROR [django.server:212] "GET /operations/approve_business_number HTTP/1.1" 500 113834
[16/Jul/2023 12:48:11] ERROR [django.request:241] Internal Server Error: /operations/approve_business_number
Traceback (most recent call last):
  File "/home/dennis/projects/saving_record/saving/lib/python3.10/site-packages/django/core/handlers/exception.py", line 55, in inner
    response = get_response(request)
  File "/home/dennis/projects/saving_record/saving/lib/python3.10/site-packages/django/core/handlers/base.py", line 197, in _get_response
    response = wrapped_callback(request, *callback_args, **callback_kwargs)
  File "/home/dennis/projects/saving_record/savingrecord/userdata/views.py", line 128, in business_number_approval
    bus_num = Company.objects.filter(buss_number__isnull=True).fiest()
  File "/home/dennis/projects/saving_record/saving/lib/python3.10/site-packages/django/db/models/manager.py", line 87, in manager_method
    return getattr(self.get_queryset(), name)(*args, **kwargs)
  File "/home/dennis/projects/saving_record/saving/lib/python3.10/site-packages/django/db/models/query.py", line 1436, in filter
    return self._filter_or_exclude(False, args, kwargs)
  File "/home/dennis/projects/saving_record/saving/lib/python3.10/site-packages/django/db/models/query.py", line 1454, in _filter_or_exclude
    clone._filter_or_exclude_inplace(negate, args, kwargs)
  File "/home/dennis/projects/saving_record/saving/lib/python3.10/site-packages/django/db/models/query.py", line 1461, in _filter_or_exclude_inplace
    self._query.add_q(Q(*args, **kwargs))
  File "/home/dennis/projects/saving_record/saving/lib/python3.10/site-packages/django/db/models/sql/query.py", line 1534, in add_q
    clause, _ = self._add_q(q_object, self.used_aliases)
  File "/home/dennis/projects/saving_record/saving/lib/python3.10/site-packages/django/db/models/sql/query.py", line 1565, in _add_q
    child_clause, needed_inner = self.build_filter(
  File "/home/dennis/projects/saving_record/saving/lib/python3.10/site-packages/django/db/models/sql/query.py", line 1415, in build_filter
    lookups, parts, reffed_expression = self.solve_lookup_type(arg, summarize)
  File "/home/dennis/projects/saving_record/saving/lib/python3.10/site-packages/django/db/models/sql/query.py", line 1225, in solve_lookup_type
    _, field, _, lookup_parts = self.names_to_path(lookup_splitted, self.get_meta())
  File "/home/dennis/projects/saving_record/saving/lib/python3.10/site-packages/django/db/models/sql/query.py", line 1713, in names_to_path
    raise FieldError(
django.core.exceptions.FieldError: Cannot resolve keyword 'buss_number' into field. Choices are: address, admin_review, approved, business_numbers, contact, country, email, id, name, registered_on
[16/Jul/2023 12:48:11] ERROR [django.server:212] "GET /operations/approve_business_number HTTP/1.1" 500 113834
[16/Jul/2023 12:48:14] ERROR [django.request:241] Internal Server Error: /operations/approve_business_number
Traceback (most recent call last):
  File "/home/dennis/projects/saving_record/saving/lib/python3.10/site-packages/django/core/handlers/exception.py", line 55, in inner
    response = get_response(request)
  File "/home/dennis/projects/saving_record/saving/lib/python3.10/site-packages/django/core/handlers/base.py", line 197, in _get_response
    response = wrapped_callback(request, *callback_args, **callback_kwargs)
  File "/home/dennis/projects/saving_record/savingrecord/userdata/views.py", line 128, in business_number_approval
    bus_num = Company.objects.filter(buss_number__isnull=True).fiest()
  File "/home/dennis/projects/saving_record/saving/lib/python3.10/site-packages/django/db/models/manager.py", line 87, in manager_method
    return getattr(self.get_queryset(), name)(*args, **kwargs)
  File "/home/dennis/projects/saving_record/saving/lib/python3.10/site-packages/django/db/models/query.py", line 1436, in filter
    return self._filter_or_exclude(False, args, kwargs)
  File "/home/dennis/projects/saving_record/saving/lib/python3.10/site-packages/django/db/models/query.py", line 1454, in _filter_or_exclude
    clone._filter_or_exclude_inplace(negate, args, kwargs)
  File "/home/dennis/projects/saving_record/saving/lib/python3.10/site-packages/django/db/models/query.py", line 1461, in _filter_or_exclude_inplace
    self._query.add_q(Q(*args, **kwargs))
  File "/home/dennis/projects/saving_record/saving/lib/python3.10/site-packages/django/db/models/sql/query.py", line 1534, in add_q
    clause, _ = self._add_q(q_object, self.used_aliases)
  File "/home/dennis/projects/saving_record/saving/lib/python3.10/site-packages/django/db/models/sql/query.py", line 1565, in _add_q
    child_clause, needed_inner = self.build_filter(
  File "/home/dennis/projects/saving_record/saving/lib/python3.10/site-packages/django/db/models/sql/query.py", line 1415, in build_filter
    lookups, parts, reffed_expression = self.solve_lookup_type(arg, summarize)
  File "/home/dennis/projects/saving_record/saving/lib/python3.10/site-packages/django/db/models/sql/query.py", line 1225, in solve_lookup_type
    _, field, _, lookup_parts = self.names_to_path(lookup_splitted, self.get_meta())
  File "/home/dennis/projects/saving_record/saving/lib/python3.10/site-packages/django/db/models/sql/query.py", line 1713, in names_to_path
    raise FieldError(
django.core.exceptions.FieldError: Cannot resolve keyword 'buss_number' into field. Choices are: address, admin_review, approved, business_numbers, contact, country, email, id, name, registered_on
[16/Jul/2023 12:48:14] ERROR [django.server:212] "GET /operations/approve_business_number HTTP/1.1" 500 113697
[16/Jul/2023 12:49:49] ERROR [django.request:241] Internal Server Error: /operations/approve_business_number
Traceback (most recent call last):
  File "/home/dennis/projects/saving_record/saving/lib/python3.10/site-packages/django/core/handlers/exception.py", line 55, in inner
    response = get_response(request)
  File "/home/dennis/projects/saving_record/saving/lib/python3.10/site-packages/django/core/handlers/base.py", line 197, in _get_response
    response = wrapped_callback(request, *callback_args, **callback_kwargs)
  File "/home/dennis/projects/saving_record/savingrecord/userdata/views.py", line 128, in business_number_approval
    bus_num = Company.objects.filter(business_numbers__isnull=True).fiest()
AttributeError: 'QuerySet' object has no attribute 'fiest'
[16/Jul/2023 12:49:49] ERROR [django.server:212] "GET /operations/approve_business_number HTTP/1.1" 500 69796
[16/Jul/2023 12:50:31] ERROR [django.request:241] Internal Server Error: /operations/approve_business_number
Traceback (most recent call last):
  File "/home/dennis/projects/saving_record/saving/lib/python3.10/site-packages/django/core/handlers/exception.py", line 55, in inner
    response = get_response(request)
  File "/home/dennis/projects/saving_record/saving/lib/python3.10/site-packages/django/core/handlers/base.py", line 197, in _get_response
    response = wrapped_callback(request, *callback_args, **callback_kwargs)
  File "/home/dennis/projects/saving_record/savingrecord/userdata/views.py", line 137, in business_number_approval
    b_form = EditBusinessNumberForm(request.POST, instance=bus_num.businessnumber)
AttributeError: 'NoneType' object has no attribute 'businessnumber'
[16/Jul/2023 12:50:31] ERROR [django.server:212] "GET /operations/approve_business_number HTTP/1.1" 500 70191
[16/Jul/2023 12:52:11] ERROR [django.request:241] Internal Server Error: /operations/approve_business_number
Traceback (most recent call last):
  File "/home/dennis/projects/saving_record/saving/lib/python3.10/site-packages/django/core/handlers/exception.py", line 55, in inner
    response = get_response(request)
  File "/home/dennis/projects/saving_record/saving/lib/python3.10/site-packages/django/core/handlers/base.py", line 197, in _get_response
    response = wrapped_callback(request, *callback_args, **callback_kwargs)
  File "/home/dennis/projects/saving_record/savingrecord/userdata/views.py", line 137, in business_number_approval
    b_form = EditBusinessNumberForm(request.POST, instance=bus_num.business_numbers)
AttributeError: 'NoneType' object has no attribute 'business_numbers'
[16/Jul/2023 12:52:11] ERROR [django.server:212] "GET /operations/approve_business_number HTTP/1.1" 500 70203
[16/Jul/2023 12:55:19] ERROR [django.request:241] Internal Server Error: /operations/approve_business_number
Traceback (most recent call last):
  File "/home/dennis/projects/saving_record/saving/lib/python3.10/site-packages/django/core/handlers/exception.py", line 55, in inner
    response = get_response(request)
  File "/home/dennis/projects/saving_record/saving/lib/python3.10/site-packages/django/core/handlers/base.py", line 197, in _get_response
    response = wrapped_callback(request, *callback_args, **callback_kwargs)
  File "/home/dennis/projects/saving_record/savingrecord/userdata/views.py", line 137, in business_number_approval
    b_form = EditBusinessNumberForm(request.POST, instance=bus_num.businessnumber)
AttributeError: 'NoneType' object has no attribute 'businessnumber'
[16/Jul/2023 12:55:19] ERROR [django.server:212] "GET /operations/approve_business_number HTTP/1.1" 500 70191
[16/Jul/2023 13:12:00] ERROR [django.request:241] Internal Server Error: /operations/approve_business_number
Traceback (most recent call last):
  File "/home/dennis/projects/saving_record/saving/lib/python3.10/site-packages/django/core/handlers/exception.py", line 55, in inner
    response = get_response(request)
  File "/home/dennis/projects/saving_record/saving/lib/python3.10/site-packages/django/core/handlers/base.py", line 197, in _get_response
    response = wrapped_callback(request, *callback_args, **callback_kwargs)
  File "/home/dennis/projects/saving_record/savingrecord/userdata/views.py", line 153, in business_number_approval
    return render(request, "userdata/business_number_approval.html", context)
UnboundLocalError: local variable 'context' referenced before assignment
[16/Jul/2023 13:12:00] ERROR [django.server:212] "GET /operations/approve_business_number HTTP/1.1" 500 69761
[16/Jul/2023 13:13:53] ERROR [django.request:241] Internal Server Error: /operations/approve_business_number
Traceback (most recent call last):
  File "/home/dennis/projects/saving_record/saving/lib/python3.10/site-packages/django/core/handlers/exception.py", line 55, in inner
    response = get_response(request)
  File "/home/dennis/projects/saving_record/saving/lib/python3.10/site-packages/django/core/handlers/base.py", line 197, in _get_response
    response = wrapped_callback(request, *callback_args, **callback_kwargs)
  File "/home/dennis/projects/saving_record/savingrecord/userdata/views.py", line 154, in business_number_approval
    return HttpResponse("No company found without a business number.")
NameError: name 'HttpResponse' is not defined
[16/Jul/2023 13:13:53] ERROR [django.server:212] "GET /operations/approve_business_number HTTP/1.1" 500 69672
[16/Jul/2023 13:16:36] ERROR [django.request:241] Internal Server Error: /operations/approve_business_number
Traceback (most recent call last):
  File "/home/dennis/projects/saving_record/saving/lib/python3.10/site-packages/django/core/handlers/exception.py", line 55, in inner
    response = get_response(request)
  File "/home/dennis/projects/saving_record/saving/lib/python3.10/site-packages/django/core/handlers/base.py", line 197, in _get_response
    response = wrapped_callback(request, *callback_args, **callback_kwargs)
  File "/home/dennis/projects/saving_record/savingrecord/userdata/views.py", line 143, in business_number_approval
    b_form = EditBusinessNumberForm(instance=bus_num.businessnumber)
AttributeError: 'Company' object has no attribute 'businessnumber'
[16/Jul/2023 13:16:36] ERROR [django.server:212] "GET /operations/approve_business_number HTTP/1.1" 500 70031
[16/Jul/2023 13:19:36] ERROR [django.request:241] Internal Server Error: /operations/approve_business_number
Traceback (most recent call last):
  File "/home/dennis/projects/saving_record/saving/lib/python3.10/site-packages/django/core/handlers/exception.py", line 55, in inner
    response = get_response(request)
  File "/home/dennis/projects/saving_record/saving/lib/python3.10/site-packages/django/core/handlers/base.py", line 197, in _get_response
    response = wrapped_callback(request, *callback_args, **callback_kwargs)
  File "/home/dennis/projects/saving_record/savingrecord/userdata/views.py", line 150, in business_number_approval
    return render(request, "userdata/business_number_approval.html", context)
  File "/home/dennis/projects/saving_record/saving/lib/python3.10/site-packages/django/shortcuts.py", line 24, in render
    content = loader.render_to_string(template_name, context, request, using=using)
  File "/home/dennis/projects/saving_record/saving/lib/python3.10/site-packages/django/template/loader.py", line 61, in render_to_string
    template = get_template(template_name, using=using)
  File "/home/dennis/projects/saving_record/saving/lib/python3.10/site-packages/django/template/loader.py", line 19, in get_template
    raise TemplateDoesNotExist(template_name, chain=chain)
django.template.exceptions.TemplateDoesNotExist: userdata/business_number_approval.html
[16/Jul/2023 13:19:36] ERROR [django.server:212] "GET /operations/approve_business_number HTTP/1.1" 500 86975
[16/Jul/2023 14:03:47] ERROR [django.request:241] Internal Server Error: /operations/admin_withdraw
Traceback (most recent call last):
  File "/home/dennis/projects/saving_record/saving/lib/python3.10/site-packages/django/utils/datastructures.py", line 84, in __getitem__
    list_ = super().__getitem__(key)
KeyError: 'withdraw_amount'

During handling of the above exception, another exception occurred:

Traceback (most recent call last):
  File "/home/dennis/projects/saving_record/saving/lib/python3.10/site-packages/django/core/handlers/exception.py", line 55, in inner
    response = get_response(request)
  File "/home/dennis/projects/saving_record/saving/lib/python3.10/site-packages/django/core/handlers/base.py", line 197, in _get_response
    response = wrapped_callback(request, *callback_args, **callback_kwargs)
  File "/home/dennis/projects/saving_record/savingrecord/userdata/views.py", line 80, in admin_widthdraw
    withdraw_amount = request.POST["withdraw_amount"]
  File "/home/dennis/projects/saving_record/saving/lib/python3.10/site-packages/django/utils/datastructures.py", line 86, in __getitem__
    raise MultiValueDictKeyError(key)
django.utils.datastructures.MultiValueDictKeyError: 'withdraw_amount'
[16/Jul/2023 14:03:47] ERROR [django.server:212] "POST /operations/admin_withdraw HTTP/1.1" 500 80103
[16/Jul/2023 14:05:53] ERROR [django.request:241] Internal Server Error: /operations/admin_withdraw
Traceback (most recent call last):
  File "/home/dennis/projects/saving_record/saving/lib/python3.10/site-packages/django/utils/datastructures.py", line 84, in __getitem__
    list_ = super().__getitem__(key)
KeyError: 'withdraw_amount'

During handling of the above exception, another exception occurred:

Traceback (most recent call last):
  File "/home/dennis/projects/saving_record/saving/lib/python3.10/site-packages/django/core/handlers/exception.py", line 55, in inner
    response = get_response(request)
  File "/home/dennis/projects/saving_record/saving/lib/python3.10/site-packages/django/core/handlers/base.py", line 197, in _get_response
    response = wrapped_callback(request, *callback_args, **callback_kwargs)
  File "/home/dennis/projects/saving_record/savingrecord/userdata/views.py", line 80, in admin_widthdraw
    withdraw_amount = request.POST["withdraw_amount"]
  File "/home/dennis/projects/saving_record/saving/lib/python3.10/site-packages/django/utils/datastructures.py", line 86, in __getitem__
    raise MultiValueDictKeyError(key)
django.utils.datastructures.MultiValueDictKeyError: 'withdraw_amount'
[16/Jul/2023 14:05:53] ERROR [django.server:212] "POST /operations/admin_withdraw HTTP/1.1" 500 80103
[16/Jul/2023 14:07:19] ERROR [django.request:241] Internal Server Error: /operations/approve_business_number
Traceback (most recent call last):
  File "/home/dennis/projects/saving_record/saving/lib/python3.10/site-packages/django/core/handlers/exception.py", line 55, in inner
    response = get_response(request)
  File "/home/dennis/projects/saving_record/saving/lib/python3.10/site-packages/django/core/handlers/base.py", line 197, in _get_response
    response = wrapped_callback(request, *callback_args, **callback_kwargs)
  File "/home/dennis/projects/saving_record/savingrecord/userdata/views.py", line 136, in business_number_approval
    b_form = EditBusinessNumberForm(request.POST, instance=bus_num.businessnumber)
AttributeError: 'Company' object has no attribute 'businessnumber'
[16/Jul/2023 14:07:19] ERROR [django.server:212] "POST /operations/approve_business_number HTTP/1.1" 500 71614
[16/Jul/2023 14:10:25] ERROR [django.request:241] Internal Server Error: /operations/approve_business_number
Traceback (most recent call last):
  File "/home/dennis/projects/saving_record/saving/lib/python3.10/site-packages/django/core/handlers/exception.py", line 55, in inner
    response = get_response(request)
  File "/home/dennis/projects/saving_record/saving/lib/python3.10/site-packages/django/core/handlers/base.py", line 197, in _get_response
    response = wrapped_callback(request, *callback_args, **callback_kwargs)
  File "/home/dennis/projects/saving_record/savingrecord/userdata/views.py", line 138, in business_number_approval
    if c_form.is_valid() and b_form.is_valid():
NameError: name 'b_form' is not defined
[16/Jul/2023 14:10:25] ERROR [django.server:212] "POST /operations/approve_business_number HTTP/1.1" 500 71396
[16/Jul/2023 14:12:26] ERROR [django.request:241] Internal Server Error: /operations/approve_business_number
Traceback (most recent call last):
  File "/home/dennis/projects/saving_record/saving/lib/python3.10/site-packages/django/core/handlers/exception.py", line 55, in inner
    response = get_response(request)
  File "/home/dennis/projects/saving_record/saving/lib/python3.10/site-packages/django/core/handlers/base.py", line 197, in _get_response
    response = wrapped_callback(request, *callback_args, **callback_kwargs)
  File "/home/dennis/projects/saving_record/savingrecord/userdata/views.py", line 142, in business_number_approval
    BusinessNumber.objects.create(buss_number=business_number,
NameError: name 'BusinessNumber' is not defined
[16/Jul/2023 14:12:26] ERROR [django.server:212] "POST /operations/approve_business_number HTTP/1.1" 500 71934
[16/Jul/2023 14:13:49] ERROR [django.request:241] Internal Server Error: /operations/approve_business_number
Traceback (most recent call last):
  File "/home/dennis/projects/saving_record/saving/lib/python3.10/site-packages/django/db/backends/utils.py", line 89, in _execute
    return self.cursor.execute(sql, params)
  File "/home/dennis/projects/saving_record/saving/lib/python3.10/site-packages/django/db/backends/sqlite3/base.py", line 328, in execute
    return super().execute(query, params)
sqlite3.IntegrityError: NOT NULL constraint failed: savings_businessnumber.buss_number

The above exception was the direct cause of the following exception:

Traceback (most recent call last):
  File "/home/dennis/projects/saving_record/saving/lib/python3.10/site-packages/django/core/handlers/exception.py", line 55, in inner
    response = get_response(request)
  File "/home/dennis/projects/saving_record/saving/lib/python3.10/site-packages/django/core/handlers/base.py", line 197, in _get_response
    response = wrapped_callback(request, *callback_args, **callback_kwargs)
  File "/home/dennis/projects/saving_record/savingrecord/userdata/views.py", line 142, in business_number_approval
    BusinessNumber.objects.create(buss_number=business_number,
  File "/home/dennis/projects/saving_record/saving/lib/python3.10/site-packages/django/db/models/manager.py", line 87, in manager_method
    return getattr(self.get_queryset(), name)(*args, **kwargs)
  File "/home/dennis/projects/saving_record/saving/lib/python3.10/site-packages/django/db/models/query.py", line 658, in create
    obj.save(force_insert=True, using=self.db)
  File "/home/dennis/projects/saving_record/saving/lib/python3.10/site-packages/django/db/models/base.py", line 814, in save
    self.save_base(
  File "/home/dennis/projects/saving_record/saving/lib/python3.10/site-packages/django/db/models/base.py", line 877, in save_base
    updated = self._save_table(
  File "/home/dennis/projects/saving_record/saving/lib/python3.10/site-packages/django/db/models/base.py", line 1020, in _save_table
    results = self._do_insert(
  File "/home/dennis/projects/saving_record/saving/lib/python3.10/site-packages/django/db/models/base.py", line 1061, in _do_insert
    return manager._insert(
  File "/home/dennis/projects/saving_record/saving/lib/python3.10/site-packages/django/db/models/manager.py", line 87, in manager_method
    return getattr(self.get_queryset(), name)(*args, **kwargs)
  File "/home/dennis/projects/saving_record/saving/lib/python3.10/site-packages/django/db/models/query.py", line 1805, in _insert
    return query.get_compiler(using=using).execute_sql(returning_fields)
  File "/home/dennis/projects/saving_record/saving/lib/python3.10/site-packages/django/db/models/sql/compiler.py", line 1822, in execute_sql
    cursor.execute(sql, params)
  File "/home/dennis/projects/saving_record/saving/lib/python3.10/site-packages/django/db/backends/utils.py", line 102, in execute
    return super().execute(sql, params)
  File "/home/dennis/projects/saving_record/saving/lib/python3.10/site-packages/django/db/backends/utils.py", line 67, in execute
    return self._execute_with_wrappers(
  File "/home/dennis/projects/saving_record/saving/lib/python3.10/site-packages/django/db/backends/utils.py", line 80, in _execute_with_wrappers
    return executor(sql, params, many, context)
  File "/home/dennis/projects/saving_record/saving/lib/python3.10/site-packages/django/db/backends/utils.py", line 84, in _execute
    with self.db.wrap_database_errors:
  File "/home/dennis/projects/saving_record/saving/lib/python3.10/site-packages/django/db/utils.py", line 91, in __exit__
    raise dj_exc_value.with_traceback(traceback) from exc_value
  File "/home/dennis/projects/saving_record/saving/lib/python3.10/site-packages/django/db/backends/utils.py", line 89, in _execute
    return self.cursor.execute(sql, params)
  File "/home/dennis/projects/saving_record/saving/lib/python3.10/site-packages/django/db/backends/sqlite3/base.py", line 328, in execute
    return super().execute(query, params)
django.db.utils.IntegrityError: NOT NULL constraint failed: savings_businessnumber.buss_number
[16/Jul/2023 14:13:49] ERROR [django.server:212] "POST /operations/approve_business_number HTTP/1.1" 500 159814
[16/Jul/2023 14:34:37] ERROR [django.request:241] Internal Server Error: /operations/approve_business_number
Traceback (most recent call last):
  File "/home/dennis/projects/saving_record/saving/lib/python3.10/site-packages/django/template/base.py", line 505, in parse
    compile_func = self.tags[command]
KeyError: 'endfor'

During handling of the above exception, another exception occurred:

Traceback (most recent call last):
  File "/home/dennis/projects/saving_record/saving/lib/python3.10/site-packages/django/core/handlers/exception.py", line 55, in inner
    response = get_response(request)
  File "/home/dennis/projects/saving_record/saving/lib/python3.10/site-packages/django/core/handlers/base.py", line 197, in _get_response
    response = wrapped_callback(request, *callback_args, **callback_kwargs)
  File "/home/dennis/projects/saving_record/savingrecord/userdata/views.py", line 163, in business_number_approval
    return render(request, "userdata/business_number_approval.html", context)
  File "/home/dennis/projects/saving_record/saving/lib/python3.10/site-packages/django/shortcuts.py", line 24, in render
    content = loader.render_to_string(template_name, context, request, using=using)
  File "/home/dennis/projects/saving_record/saving/lib/python3.10/site-packages/django/template/loader.py", line 61, in render_to_string
    template = get_template(template_name, using=using)
  File "/home/dennis/projects/saving_record/saving/lib/python3.10/site-packages/django/template/loader.py", line 15, in get_template
    return engine.get_template(template_name)
  File "/home/dennis/projects/saving_record/saving/lib/python3.10/site-packages/django/template/backends/django.py", line 33, in get_template
    return Template(self.engine.get_template(template_name), self)
  File "/home/dennis/projects/saving_record/saving/lib/python3.10/site-packages/django/template/engine.py", line 175, in get_template
    template, origin = self.find_template(template_name)
  File "/home/dennis/projects/saving_record/saving/lib/python3.10/site-packages/django/template/engine.py", line 157, in find_template
    template = loader.get_template(name, skip=skip)
  File "/home/dennis/projects/saving_record/saving/lib/python3.10/site-packages/django/template/loaders/cached.py", line 57, in get_template
    template = super().get_template(template_name, skip)
  File "/home/dennis/projects/saving_record/saving/lib/python3.10/site-packages/django/template/loaders/base.py", line 28, in get_template
    return Template(
  File "/home/dennis/projects/saving_record/saving/lib/python3.10/site-packages/django/template/base.py", line 154, in __init__
    self.nodelist = self.compile_nodelist()
  File "/home/dennis/projects/saving_record/saving/lib/python3.10/site-packages/django/template/base.py", line 200, in compile_nodelist
    return parser.parse()
  File "/home/dennis/projects/saving_record/saving/lib/python3.10/site-packages/django/template/base.py", line 513, in parse
    raise self.error(token, e)
  File "/home/dennis/projects/saving_record/saving/lib/python3.10/site-packages/django/template/base.py", line 511, in parse
    compiled_result = compile_func(self, token)
  File "/home/dennis/projects/saving_record/saving/lib/python3.10/site-packages/django/template/loader_tags.py", line 293, in do_extends
    nodelist = parser.parse()
  File "/home/dennis/projects/saving_record/saving/lib/python3.10/site-packages/django/template/base.py", line 513, in parse
    raise self.error(token, e)
  File "/home/dennis/projects/saving_record/saving/lib/python3.10/site-packages/django/template/base.py", line 511, in parse
    compiled_result = compile_func(self, token)
  File "/home/dennis/projects/saving_record/saving/lib/python3.10/site-packages/django/template/loader_tags.py", line 232, in do_block
    nodelist = parser.parse(("endblock",))
  File "/home/dennis/projects/saving_record/saving/lib/python3.10/site-packages/django/template/base.py", line 513, in parse
    raise self.error(token, e)
  File "/home/dennis/projects/saving_record/saving/lib/python3.10/site-packages/django/template/base.py", line 511, in parse
    compiled_result = compile_func(self, token)
  File "/home/dennis/projects/saving_record/saving/lib/python3.10/site-packages/django/template/defaulttags.py", line 967, in do_if
    nodelist = parser.parse(("endif",))
  File "/home/dennis/projects/saving_record/saving/lib/python3.10/site-packages/django/template/base.py", line 507, in parse
    self.invalid_block_tag(token, command, parse_until)
  File "/home/dennis/projects/saving_record/saving/lib/python3.10/site-packages/django/template/base.py", line 558, in invalid_block_tag
    raise self.error(
django.template.exceptions.TemplateSyntaxError: Invalid block tag on line 45: 'endfor', expected 'endif'. Did you forget to register or load this tag?
[16/Jul/2023 14:34:37] ERROR [django.server:212] "GET /operations/approve_business_number HTTP/1.1" 500 192783
[16/Jul/2023 15:28:55] ERROR [django.request:241] Internal Server Error: /operations/approve_till_number
Traceback (most recent call last):
  File "/home/dennis/projects/saving_record/saving/lib/python3.10/site-packages/django/core/handlers/exception.py", line 55, in inner
    response = get_response(request)
  File "/home/dennis/projects/saving_record/saving/lib/python3.10/site-packages/django/core/handlers/base.py", line 197, in _get_response
    response = wrapped_callback(request, *callback_args, **callback_kwargs)
  File "/home/dennis/projects/saving_record/savingrecord/userdata/views.py", line 170, in till_number_approval
    till_num = Agents.objects.filter(agent_number__isnull=True).first()
NameError: name 'Agents' is not defined
[16/Jul/2023 15:28:55] ERROR [django.server:212] "GET /operations/approve_till_number HTTP/1.1" 500 69691
[16/Jul/2023 15:33:06] ERROR [django.request:241] Internal Server Error: /operations/approve_till_number
Traceback (most recent call last):
  File "/home/dennis/projects/saving_record/saving/lib/python3.10/site-packages/django/core/handlers/exception.py", line 55, in inner
    response = get_response(request)
  File "/home/dennis/projects/saving_record/saving/lib/python3.10/site-packages/django/core/handlers/base.py", line 197, in _get_response
    response = wrapped_callback(request, *callback_args, **callback_kwargs)
  File "/home/dennis/projects/saving_record/savingrecord/userdata/views.py", line 194, in till_number_approval
    return render(request, "userdata/till_number_approval.html", context)
  File "/home/dennis/projects/saving_record/saving/lib/python3.10/site-packages/django/shortcuts.py", line 24, in render
    content = loader.render_to_string(template_name, context, request, using=using)
  File "/home/dennis/projects/saving_record/saving/lib/python3.10/site-packages/django/template/loader.py", line 61, in render_to_string
    template = get_template(template_name, using=using)
  File "/home/dennis/projects/saving_record/saving/lib/python3.10/site-packages/django/template/loader.py", line 19, in get_template
    raise TemplateDoesNotExist(template_name, chain=chain)
django.template.exceptions.TemplateDoesNotExist: userdata/till_number_approval.html
[16/Jul/2023 15:33:06] ERROR [django.server:212] "GET /operations/approve_till_number HTTP/1.1" 500 86545
[16/Jul/2023 15:46:36] ERROR [django.request:241] Internal Server Error: /operations/approve_till_number
Traceback (most recent call last):
  File "/home/dennis/projects/saving_record/saving/lib/python3.10/site-packages/django/core/handlers/exception.py", line 55, in inner
    response = get_response(request)
  File "/home/dennis/projects/saving_record/saving/lib/python3.10/site-packages/django/core/handlers/base.py", line 197, in _get_response
    response = wrapped_callback(request, *callback_args, **callback_kwargs)
  File "/home/dennis/projects/saving_record/savingrecord/userdata/views.py", line 191, in till_number_approval
    "till_form": till_form,
UnboundLocalError: local variable 'till_form' referenced before assignment
[16/Jul/2023 15:46:36] ERROR [django.server:212] "GET /operations/approve_till_number HTTP/1.1" 500 70432
[16/Jul/2023 15:51:30] ERROR [django.request:241] Internal Server Error: /operations/approve_till_number
Traceback (most recent call last):
  File "/home/dennis/projects/saving_record/saving/lib/python3.10/site-packages/django/template/base.py", line 505, in parse
    compile_func = self.tags[command]
KeyError: 'endfor'

During handling of the above exception, another exception occurred:

Traceback (most recent call last):
  File "/home/dennis/projects/saving_record/saving/lib/python3.10/site-packages/django/core/handlers/exception.py", line 55, in inner
    response = get_response(request)
  File "/home/dennis/projects/saving_record/saving/lib/python3.10/site-packages/django/core/handlers/base.py", line 197, in _get_response
    response = wrapped_callback(request, *callback_args, **callback_kwargs)
  File "/home/dennis/projects/saving_record/savingrecord/userdata/views.py", line 194, in till_number_approval
    return render(request, "userdata/till_number_approval.html", context)
  File "/home/dennis/projects/saving_record/saving/lib/python3.10/site-packages/django/shortcuts.py", line 24, in render
    content = loader.render_to_string(template_name, context, request, using=using)
  File "/home/dennis/projects/saving_record/saving/lib/python3.10/site-packages/django/template/loader.py", line 61, in render_to_string
    template = get_template(template_name, using=using)
  File "/home/dennis/projects/saving_record/saving/lib/python3.10/site-packages/django/template/loader.py", line 15, in get_template
    return engine.get_template(template_name)
  File "/home/dennis/projects/saving_record/saving/lib/python3.10/site-packages/django/template/backends/django.py", line 33, in get_template
    return Template(self.engine.get_template(template_name), self)
  File "/home/dennis/projects/saving_record/saving/lib/python3.10/site-packages/django/template/engine.py", line 175, in get_template
    template, origin = self.find_template(template_name)
  File "/home/dennis/projects/saving_record/saving/lib/python3.10/site-packages/django/template/engine.py", line 157, in find_template
    template = loader.get_template(name, skip=skip)
  File "/home/dennis/projects/saving_record/saving/lib/python3.10/site-packages/django/template/loaders/cached.py", line 57, in get_template
    template = super().get_template(template_name, skip)
  File "/home/dennis/projects/saving_record/saving/lib/python3.10/site-packages/django/template/loaders/base.py", line 28, in get_template
    return Template(
  File "/home/dennis/projects/saving_record/saving/lib/python3.10/site-packages/django/template/base.py", line 154, in __init__
    self.nodelist = self.compile_nodelist()
  File "/home/dennis/projects/saving_record/saving/lib/python3.10/site-packages/django/template/base.py", line 200, in compile_nodelist
    return parser.parse()
  File "/home/dennis/projects/saving_record/saving/lib/python3.10/site-packages/django/template/base.py", line 513, in parse
    raise self.error(token, e)
  File "/home/dennis/projects/saving_record/saving/lib/python3.10/site-packages/django/template/base.py", line 511, in parse
    compiled_result = compile_func(self, token)
  File "/home/dennis/projects/saving_record/saving/lib/python3.10/site-packages/django/template/loader_tags.py", line 293, in do_extends
    nodelist = parser.parse()
  File "/home/dennis/projects/saving_record/saving/lib/python3.10/site-packages/django/template/base.py", line 513, in parse
    raise self.error(token, e)
  File "/home/dennis/projects/saving_record/saving/lib/python3.10/site-packages/django/template/base.py", line 511, in parse
    compiled_result = compile_func(self, token)
  File "/home/dennis/projects/saving_record/saving/lib/python3.10/site-packages/django/template/loader_tags.py", line 232, in do_block
    nodelist = parser.parse(("endblock",))
  File "/home/dennis/projects/saving_record/saving/lib/python3.10/site-packages/django/template/base.py", line 507, in parse
    self.invalid_block_tag(token, command, parse_until)
  File "/home/dennis/projects/saving_record/saving/lib/python3.10/site-packages/django/template/base.py", line 558, in invalid_block_tag
    raise self.error(
django.template.exceptions.TemplateSyntaxError: Invalid block tag on line 44: 'endfor', expected 'endblock'. Did you forget to register or load this tag?
[16/Jul/2023 15:51:30] ERROR [django.server:212] "GET /operations/approve_till_number HTTP/1.1" 500 177618
[16/Jul/2023 16:05:40] ERROR [django.request:241] Internal Server Error: /operations/approve_till_number
Traceback (most recent call last):
  File "/home/dennis/projects/saving_record/saving/lib/python3.10/site-packages/django/core/handlers/exception.py", line 55, in inner
    response = get_response(request)
  File "/home/dennis/projects/saving_record/saving/lib/python3.10/site-packages/django/core/handlers/base.py", line 197, in _get_response
    response = wrapped_callback(request, *callback_args, **callback_kwargs)
  File "/home/dennis/projects/saving_record/savingrecord/userdata/views.py", line 183, in till_number_approval
    TillNumber.objects.create(till_numbers=till_number, agent=till_num)
  File "/home/dennis/projects/saving_record/saving/lib/python3.10/site-packages/django/db/models/manager.py", line 87, in manager_method
    return getattr(self.get_queryset(), name)(*args, **kwargs)
  File "/home/dennis/projects/saving_record/saving/lib/python3.10/site-packages/django/db/models/query.py", line 656, in create
    obj = self.model(**kwargs)
  File "/home/dennis/projects/saving_record/saving/lib/python3.10/site-packages/django/db/models/base.py", line 567, in __init__
    raise TypeError(
TypeError: TillNumber() got unexpected keyword arguments: 'till_numbers'
[16/Jul/2023 16:05:40] ERROR [django.server:212] "POST /operations/approve_till_number HTTP/1.1" 500 87924
[16/Jul/2023 16:40:04] ERROR [django.request:241] Internal Server Error: /operations/approve_till_number
Traceback (most recent call last):
  File "/home/dennis/projects/saving_record/saving/lib/python3.10/site-packages/django/core/handlers/exception.py", line 55, in inner
    response = get_response(request)
  File "/home/dennis/projects/saving_record/saving/lib/python3.10/site-packages/django/core/handlers/base.py", line 197, in _get_response
    response = wrapped_callback(request, *callback_args, **callback_kwargs)
  File "/home/dennis/projects/saving_record/savingrecord/userdata/views.py", line 183, in till_number_approval
    print(request.FILE)
AttributeError: 'WSGIRequest' object has no attribute 'FILE'
[16/Jul/2023 16:40:04] ERROR [django.server:212] "POST /operations/approve_till_number HTTP/1.1" 500 73188
